<?xml version="1.0" encoding="utf-8"?>
<robot name="rm75_inspire_left">
  <link name="world_base"/>
  <joint name="world_joint" type="fixed">
    <origin xyz="0.138497 0 0" rpy="-1.57079 1.57079 0"/>
    <parent link="world_base"/>
    <child link="arm_base"/>
  </joint>
  <link name="arm_base">
    <visual>
      <geometry>
        <mesh filename="../../arms/rm75/meshes/visual/rm75_link_0.glb"/>
      </geometry>
    </visual>
    <collision>
      <geometry>
        <mesh filename="../../arms/rm75/meshes/collision/rm75_link_0.obj"/>
      </geometry>
    </collision>
  </link>
  <link name="rm75_link_1">
    <inertial>
      <origin xyz="-0.0211077206294248 -0.0768143023644786 -0.000184059931994218" rpy="0 0 0"/>
      <mass value="0.593560332787429"/>
      <inertia ixx="0.00118168579764742" ixy="-0.000211208113035036" ixz="-7.25313887508386E-07"
               iyy="0.000561349347423681" iyz="-1.83321926915751E-06" izz="0.00126613288987183"/>
    </inertial>
    <visual>
      <geometry>
        <mesh filename="../../arms/rm75/meshes/visual/rm75_link_1.glb"/>
      </geometry>
    </visual>
    <collision>
      <geometry>
        <mesh filename="../../arms/rm75/meshes/collision/rm75_link_1.obj"/>
      </geometry>
    </collision>
  </link>
  <joint name="joint_1" type="revolute">
    <origin xyz="0 0 0" rpy="0 -1.57079 0"/>
    <parent link="arm_base"/>
    <child link="rm75_link_1"/>
    <axis xyz="0 -1 0"/>
    <limit lower="-3.14" upper="3.14" effort="0" velocity="0"/>
  </joint>
  <link name="rm75_link_2">
    <inertial>
      <origin xyz="-0.00538333319864128 -0.0761297609224655 -5.85592772051058E-08" rpy="0 0 0"/>
      <mass value="0.43285067491302"/>
      <inertia ixx="0.00122245027307076" ixy="-0.000279002266374725" ixz="-6.16288419375421E-09"
               iyy="0.000317472185553248" iyz="-1.42918067916209E-09" izz="0.00125837852309913"/>
    </inertial>
    <visual>
      <geometry>
        <mesh filename="../../arms/rm75/meshes/visual/rm75_link_2.glb"/>
      </geometry>
    </visual>
    <collision>
      <geometry>
        <mesh filename="../../arms/rm75/meshes/collision/rm75_link_2.obj"/>
      </geometry>
    </collision>
  </link>
  <joint name="joint_2" type="revolute">
    <origin xyz="0.01646 -0.102 0.00014365" rpy="0 -0.0087266 0"/>
    <parent link="rm75_link_1"/>
    <child link="rm75_link_2"/>
    <axis xyz="1 0 0"/>
    <limit lower="-3.14" upper="3.14" effort="0" velocity="0"/>
  </joint>
  <link name="rm75_link_3">
    <inertial>
      <origin xyz="-0.0229438462116271 -0.0761527997547926 -0.000202637702619191" rpy="0 0 0"/>
      <mass value="0.431323256975464"/>
      <inertia ixx="0.000730375831773939" ixy="-0.000142609868347039" ixz="-5.51348702629857E-07"
               iyy="0.000315056960779462" iyz="-1.24420805510127E-06" izz="0.000794323182493074"/>
    </inertial>
    <visual>
      <geometry>
        <mesh filename="../../arms/rm75/meshes/visual/rm75_link_3.glb"/>
      </geometry>
    </visual>
    <collision>
      <geometry>
        <mesh filename="../../arms/rm75/meshes/collision/rm75_link_3.obj"/>
      </geometry>
    </collision>
  </link>
  <joint name="joint_3" type="revolute">
    <origin xyz="-0.017061 -0.1525 0" rpy="0 0.0087266 0"/>
    <parent link="rm75_link_2"/>
    <child link="rm75_link_3"/>
    <axis xyz="0 -1 0"/>
    <limit lower="-3.14" upper="3.14" effort="0" velocity="0"/>
  </joint>
  <link name="rm75_link_4">
    <inertial>
      <origin xyz="-0.00266694591650199 -0.0595927393682475 -4.43204636102479E-06" rpy="0 0 0"/>
      <mass value="0.289640633455538"/>
      <inertia ixx="0.000614175096706907" ixy="-0.000144607251054507" ixz="3.36058890161805E-08"
               iyy="0.000156487088714941" iyz="5.86786617519025E-08" izz="0.000637363568489521"/>
    </inertial>
    <visual>
      <geometry>
        <mesh filename="../../arms/rm75/meshes/visual/rm75_link_4.glb"/>
      </geometry>
    </visual>
    <collision>
      <geometry>
        <mesh filename="../../arms/rm75/meshes/collision/rm75_link_4.obj"/>
      </geometry>
    </collision>
  </link>
  <joint name="joint_4" type="revolute">
    <origin xyz="0.013535 -0.1035 0.00011701" rpy="0 -0.0087266 0"/>
    <parent link="rm75_link_3"/>
    <child link="rm75_link_4"/>
    <axis xyz="1 0 0"/>
    <limit lower="-3.14" upper="3.14" effort="0" velocity="0"/>
  </joint>
  <link name="rm75_link_5">
    <inertial>
      <origin xyz="-0.0180416196430215 -0.0599608557029523 -0.000158546565612205" rpy="0 0 0"/>
      <mass value="0.2394192926691"/>
      <inertia ixx="0.000262731128614883" ixy="-4.42355773627576E-05" ixz="-2.04745867573492E-07"
               iyy="0.000119890319412695" iyz="-3.87391677184994E-07" izz="0.000285939963268203"/>
    </inertial>
    <visual>
      <geometry>
        <mesh filename="../../arms/rm75/meshes/visual/rm75_link_5.glb"/>
      </geometry>
    </visual>
    <collision>
      <geometry>
        <mesh filename="../../arms/rm75/meshes/collision/rm75_link_5.obj"/>
      </geometry>
    </collision>
  </link>
  <joint name="joint_5" type="revolute">
    <origin xyz="-0.013236 -0.1285 0" rpy="0 0.0087266 0"/>
    <parent link="rm75_link_4"/>
    <child link="rm75_link_5"/>
    <axis xyz="0 -1 0"/>
    <limit lower="-3.14" upper="3.14" effort="0" velocity="0"/>
  </joint>
  <link name="rm75_link_6">
    <inertial>
      <origin xyz="-0.00506760113925948 -0.0593814209380522 -3.67703718251455E-06" rpy="0 0 0"/>
      <mass value="0.218795686891305"/>
      <inertia ixx="0.000334476012884826" ixy="-7.82422122764673E-05" ixz="1.62433433910283E-08"
               iyy="0.000104927345235043" iyz="2.94094695871064E-08" izz="0.000350535563728772"/>
    </inertial>
    <visual>
      <geometry>
        <mesh filename="../../arms/rm75/meshes/visual/rm75_link_6.glb"/>
      </geometry>
    </visual>
    <collision>
      <geometry>
        <mesh filename="../../arms/rm75/meshes/collision/rm75_link_6.obj"/>
      </geometry>
    </collision>
  </link>
  <joint name="joint_6" type="revolute">
    <origin xyz="0.012136 -0.0815 0.00010591" rpy="0 -0.0087266 0"/>
    <parent link="rm75_link_5"/>
    <child link="rm75_link_6"/>
    <axis xyz="1 0 0"/>
    <limit lower="-3.14" upper="3.14" effort="0" velocity="0"/>
  </joint>
  <link name="rm75_link_7">
    <inertial>
      <origin xyz="0.0007182 -0.00039901 -0.012697" rpy="0 0 0"/>
      <mass value="0.18088"/>
      <inertia ixx="5.6496E-05" ixy="-3.7101E-06" ixz="-7.5579E-08" iyy="5.2359E-05"
               iyz="1.1327E-08" izz="8.8503E-05"/>
    </inertial>
    <visual>
      <origin xyz="0 0 0" rpy=" 0 0 -1.047197 "/>
      <geometry>
        <mesh filename="../../arms/rm75/meshes/visual/rm75_link_7.glb"/>
      </geometry>
    </visual>
    <collision>
      <origin xyz="0 0 0" rpy=" 0 0 -1.047197 "/>
      <geometry>
        <mesh filename="../../arms/rm75/meshes/collision/rm75_link_7.obj"/>
      </geometry>
    </collision>
  </link>
  <joint name="joint_7" type="revolute">
    <origin xyz="-0.012436 -0.144 0" rpy="1.57059 0 0"/>
    <parent link="rm75_link_6"/>
    <child link="rm75_link_7"/>
    <axis xyz="0 0 1"/>
    <limit lower="-3.14" upper="3.14" effort="100" velocity="1"/>
  </joint>
  <link name="ee_link"/>
  <joint name="ee_joint" type="fixed">
    <parent link="rm75_link_7"/>
    <child link="ee_link"/>
    <origin rpy="0 0 3.14159" xyz="0 0 0"/>
  </joint>

  <!--  left hand-->
  <joint name="hand_base_joint" type="fixed">
    <parent link="rm75_link_7"/>
    <child link="hand_base_link"/>
    <origin xyz="0 0 0" rpy="-1.57079 0 0"/>
  </joint>
  <link name="hand_base_link">
    <inertial>
      <origin xyz="-0.0025264 -0.066047 -0.0019598" rpy="0 0 0"/>
      <mass value="0.14143"/>
      <inertia ixx="0.00012281" ixy="2.1711E-06" ixz="1.7709E-06" iyy="8.3832E-05" iyz="-1.6551E-06" izz="7.6663E-05"/>
    </inertial>
    <visual>
      <origin xyz="0 0 0" rpy="0 0 0"/>
      <geometry>
        <mesh filename="../../hands/inspire_hand/meshes/visual/left_base_link.glb"/>
      </geometry>
    </visual>
    <collision>
      <origin xyz="0 -0.0136 0" rpy="1.57079 0 0"/>
      <geometry>
        <cylinder length="0.0278" radius="0.028"/>
      </geometry>
    </collision>
    <collision>
      <origin xyz="-0.0032 -0.038 0" rpy="0 0 0"/>
      <geometry>
        <box size="0.0391 0.0202 0.0574"/>
      </geometry>
    </collision>
    <collision>
      <origin xyz="-0.0032 -0.0682 0" rpy="0 0 0"/>
      <geometry>
        <box size="0.0391 0.04 0.0814"/>
      </geometry>
    </collision>
    <collision>
      <origin xyz="0 -0.1081 0" rpy="0 0 0"/>
      <geometry>
        <box size="0.0322 0.04 0.0814"/>
      </geometry>
    </collision>
    <collision>
      <origin xyz="-0.0016 -0.1340 -0.0309" rpy="0 0 0"/>
      <geometry>
        <box size="0.0125 0.0111 0.0089"/>
      </geometry>
    </collision>
    <collision>
      <origin xyz="-0.0016 -0.1340 -0.0118" rpy="0 0 0"/>
      <geometry>
        <box size="0.0125 0.0111 0.0089"/>
      </geometry>
    </collision>
    <collision>
      <origin xyz="-0.0016 -0.1340 0.0070" rpy="0 0 0"/>
      <geometry>
        <box size="0.0125 0.0111 0.0089"/>
      </geometry>
    </collision>
    <collision>
      <origin xyz="-0.0016 -0.1340 0.0262" rpy="0 0 0"/>
      <geometry>
        <box size="0.0125 0.0111 0.0089"/>
      </geometry>
    </collision>
  </link>
  <link name="thumb_proximal_base">
    <inertial>
      <origin xyz="0.0048817 0.0009382 -0.00722" rpy="0 0 0"/>
      <mass value="0.0018869"/>
      <inertia ixx="5.816E-08" ixy="-1.4539E-08" ixz="-4.491E-09" iyy="7.9161E-08" iyz="-1.8727E-09" izz="6.7433E-08"/>
    </inertial>
    <visual>
      <origin xyz="0 0 0" rpy="0 0 0"/>
      <geometry>
        <mesh filename="../../hands/inspire_hand/meshes/visual/left_thumb_proximal_base.glb"/>
      </geometry>
    </visual>
    <collision>
      <origin xyz="0 0 0" rpy="0 0 0"/>
      <geometry>
        <mesh filename="../../hands/inspire_hand/meshes/collision/left_thumb_proximal_base.obj"/>
      </geometry>
    </collision>
  </link>
  <joint name="thumb_proximal_yaw_joint" type="revolute">
    <origin xyz="-0.01696 -0.0691 0.02045" rpy="1.5708 -1.5708 0"/>
    <parent link="hand_base_link"/>
    <child link="thumb_proximal_base"/>
    <axis xyz="0 0 1"/>
    <limit lower="0" upper="1.308" effort="1" velocity="0.5"/>
  </joint>
  <link name="thumb_proximal">
    <inertial>
      <origin xyz="0.021932 -0.012785 -0.0080386" rpy="0 0 0"/>
      <mass value="0.0066075"/>
      <inertia ixx="1.5686E-06" ixy="7.8296E-07" ixz="8.9143E-10" iyy="1.7353E-06" iyz="1.0191E-09" izz="2.786E-06"/>
    </inertial>
    <visual>
      <origin xyz="0 0 0" rpy="0 0 0"/>
      <geometry>
        <mesh filename="../../hands/inspire_hand/meshes/visual/left_thumb_proximal.glb"/>
      </geometry>
    </visual>
    <collision>
      <origin xyz="0 0 0" rpy="0 0 0"/>
      <geometry>
        <mesh filename="../../hands/inspire_hand/meshes/collision/left_thumb_proximal.obj"/>
      </geometry>
    </collision>
  </link>
  <joint name="thumb_proximal_pitch_joint" type="revolute">
    <origin xyz="0.0099867 0.0098242 -0.0089" rpy="-1.5708 0 0.16939"/>
    <parent link="thumb_proximal_base"/>
    <child link="thumb_proximal"/>
    <axis xyz="0 0 -1"/>
    <limit lower="0" upper="0.6" effort="1" velocity="0.5"/>
  </joint>
  <link name="thumb_intermediate">
    <inertial>
      <origin xyz="0.0095544 0.0016282 -0.0071997" rpy="0 0 0"/>
      <mass value="0.0037847"/>
      <inertia ixx="3.6981E-07" ixy="9.8581E-08" ixz="-4.7469E-12" iyy="3.2394E-07" iyz="-1.0939E-12" izz="4.6531E-07"/>
    </inertial>
    <visual>
      <origin xyz="0 0 0" rpy="0 0 0"/>
      <geometry>
        <mesh filename="../../hands/inspire_hand/meshes/visual/left_thumb_intermediate.glb"/>
      </geometry>
    </visual>
    <collision>
      <origin xyz="0 0 0" rpy="0 0 0"/>
      <geometry>
        <mesh filename="../../hands/inspire_hand/meshes/collision/left_thumb_intermediate.obj"/>
      </geometry>
    </collision>
  </link>
  <joint name="thumb_intermediate_joint" type="revolute">
    <origin xyz="0.04407 -0.034553 -0.0008" rpy="0 0 0"/>
    <parent link="thumb_proximal"/>
    <child link="thumb_intermediate"/>
    <axis xyz="0 0 -1"/>
    <limit lower="0" upper="0.8" effort="1" velocity="0.5"/>
    <mimic joint="thumb_proximal_pitch_joint" multiplier="1.334" offset="0"/>
  </joint>
  <link name="thumb_distal">
    <inertial>
      <origin xyz="0.0092888 -0.0049529 -0.0060033" rpy="0 0 0"/>
      <mass value="0.0033441"/>
      <inertia ixx="1.3632E-07" ixy="5.6788E-08" ixz="-9.2764E-11" iyy="1.4052E-07" iyz="1.2283E-10" izz="2.0026E-07"/>
    </inertial>
    <visual>
      <origin xyz="0 0 0" rpy="0 0 0"/>
      <geometry>
        <mesh filename="../../hands/inspire_hand/meshes/visual/left_thumb_distal.glb"/>
      </geometry>
    </visual>
    <collision>
      <origin xyz="0 0 0" rpy="0 0 0"/>
      <geometry>
        <mesh filename="../../hands/inspire_hand/meshes/collision/left_thumb_distal.obj" scale="1 1 1"/>
      </geometry>
    </collision>
  </link>
  <joint name="thumb_distal_joint" type="revolute">
    <origin xyz="0.020248 -0.010156 -0.0012" rpy="0 0 0"/>
    <parent link="thumb_intermediate"/>
    <child link="thumb_distal"/>
    <axis xyz="0 0 -1"/>
    <limit lower="0" upper="0.4" effort="1" velocity="0.5"/>
    <mimic joint="thumb_proximal_pitch_joint" multiplier="0.667" offset="0"/>
  </joint>
  <link name="index_proximal">
    <inertial>
      <origin xyz="0.0012259 -0.011942 -0.0060001" rpy="0 0 0"/>
      <mass value="0.0042403"/>
      <inertia ixx="6.6232E-07" ixy="1.5775E-08" ixz="1.8515E-12" iyy="2.1146E-07" iyz="5.0828E-12" izz="6.9398E-07"/>
    </inertial>
    <visual>
      <origin xyz="0 0 0" rpy="0 0 0"/>
      <geometry>
        <mesh filename="../../hands/inspire_hand/meshes/visual/left_index_proximal.glb"/>
      </geometry>
    </visual>
    <collision>
      <origin xyz="0 0 0" rpy="0 0 0"/>
      <geometry>
        <mesh filename="../../hands/inspire_hand/meshes/collision/left_index_proximal.obj"/>
      </geometry>
    </collision>
  </link>
  <joint name="index_proximal_joint" type="revolute">
    <origin xyz="0.00028533 -0.13653 0.032268" rpy="-0.034907 0 0"/>
    <parent link="hand_base_link"/>
    <child link="index_proximal"/>
    <axis xyz="0 0 -1"/>
    <limit lower="0" upper="1.47" effort="1" velocity="0.5"/>
  </joint>
  <link name="index_intermediate">
    <inertial>
      <origin xyz="0.0019697 -0.019589 -0.005" rpy="0 0 0"/>
      <mass value="0.0045683"/>
      <inertia ixx="7.6111E-07" ixy="-8.7637E-08" ixz="-3.7751E-13" iyy="9.6076E-08" iyz="-9.9444E-13" izz="7.8179E-07"/>
    </inertial>
    <visual>
      <origin xyz="0 0 0" rpy="0 0 0"/>
      <geometry>
        <mesh filename="../../hands/inspire_hand/meshes/visual/left_index_intermediate.glb"/>
      </geometry>
    </visual>
    <collision>
      <origin xyz="0 0 0" rpy="0 0 0"/>
      <geometry>
        <mesh filename="../../hands/inspire_hand/meshes/collision/left_index_intermediate.obj"/>
      </geometry>
    </collision>
  </link>
  <joint name="index_intermediate_joint" type="revolute">
    <origin xyz="-0.0026138 -0.032026 -0.001" rpy="0 0 0"/>
    <parent link="index_proximal"/>
    <child link="index_intermediate"/>
    <axis xyz="0 0 -1"/>
    <limit lower="-0.04545" upper="1.56" effort="1" velocity="0.5"/>
    <mimic joint="index_proximal_joint" multiplier="1.06399" offset="-0.04545"/>
  </joint>
  <link name="middle_proximal">
    <inertial>
      <origin xyz="0.001297 -0.011934 -0.0060001" rpy="0 0 0"/>
      <mass value="0.0042403"/>
      <inertia ixx="6.6211E-07" ixy="1.8461E-08" ixz="1.8002E-12" iyy="2.1167E-07" iyz="6.6808E-12" izz="6.9397E-07"/>
    </inertial>
    <visual>
      <origin xyz="0 0 0" rpy="0 0 0"/>
      <geometry>
        <mesh filename="../../hands/inspire_hand/meshes/visual/left_index_proximal.glb"/>
      </geometry>
    </visual>
    <collision>
      <origin xyz="0 0 0" rpy="0 0 0"/>
      <geometry>
        <mesh filename="../../hands/inspire_hand/meshes/collision/left_index_proximal.obj"/>
      </geometry>
    </collision>
  </link>
  <joint name="middle_proximal_joint" type="revolute">
    <origin xyz="0.00028533 -0.1371 0.01295" rpy="0 0 0"/>
    <parent link="hand_base_link"/>
    <child link="middle_proximal"/>
    <axis xyz="0 0 -1"/>
    <limit lower="0" upper="1.47" effort="1" velocity="0.5"/>
  </joint>
  <link name="middle_intermediate">
    <inertial>
      <origin xyz="0.001921 -0.020796 -0.005" rpy="0 0 0"/>
      <mass value="0.0050396"/>
      <inertia ixx="9.5822E-07" ixy="-1.1425E-07" ixz="-2.4791E-12" iyy="1.0646E-07" iyz="-5.9173E-12" izz="9.8384E-07"/>
    </inertial>
    <visual>
      <origin xyz="0 0 0" rpy="0 0 0"/>
      <geometry>
        <mesh filename="../../hands/inspire_hand/meshes/visual/left_middle_intermediate.glb"/>
      </geometry>
    </visual>
    <collision>
      <origin xyz="0 0 0" rpy="0 0 0"/>
      <geometry>
        <mesh filename="../../hands/inspire_hand/meshes/collision/left_middle_intermediate.obj"/>
      </geometry>
    </collision>
  </link>
  <joint name="middle_intermediate_joint" type="revolute">
    <origin xyz="-0.0024229 -0.032041 -0.001" rpy="0 0 0"/>
    <parent link="middle_proximal"/>
    <child link="middle_intermediate"/>
    <axis xyz="0 0 -1"/>
    <limit lower="-0.04545" upper="1.56" effort="1" velocity="0.5"/>
    <mimic joint="middle_proximal_joint" multiplier="1.06399" offset="-0.04545"/>
  </joint>
  <link name="ring_proximal">
    <inertial>
      <origin xyz="0.001297 -0.011934 -0.0060002" rpy="0 0 0"/>
      <mass value="0.0042403"/>
      <inertia ixx="6.6211E-07" ixy="1.8461E-08" ixz="1.5793E-12" iyy="2.1167E-07" iyz="6.6868E-12" izz="6.9397E-07"/>
    </inertial>
    <visual>
      <origin xyz="0 0 0" rpy="0 0 0"/>
      <geometry>
        <mesh filename="../../hands/inspire_hand/meshes/visual/left_index_proximal.glb"/>
      </geometry>
    </visual>
    <collision>
      <origin xyz="0 0 0" rpy="0 0 0"/>
      <geometry>
        <mesh filename="../../hands/inspire_hand/meshes/collision/left_index_proximal.obj"/>
      </geometry>
    </collision>
  </link>
  <joint name="ring_proximal_joint" type="revolute">
    <origin xyz="0.00028533 -0.13691 -0.0062872" rpy="0.05236 0 0"/>
    <parent link="hand_base_link"/>
    <child link="ring_proximal"/>
    <axis xyz="0 0 -1"/>
    <limit lower="0" upper="1.47" effort="1" velocity="0.5"/>
  </joint>
  <link name="ring_intermediate">
    <inertial>
      <origin xyz="0.0021753 -0.019567 -0.005" rpy="0 0 0"/>
      <mass value="0.0045683"/>
      <inertia ixx="7.6286E-07" ixy="-8.0635E-08" ixz="-6.1562E-13" iyy="9.431E-08" iyz="-5.8619E-13" izz="7.8177E-07"/>
    </inertial>
    <visual>
      <origin xyz="0 0 0" rpy="0 0 0"/>
      <geometry>
        <mesh filename="../../hands/inspire_hand/meshes/visual/left_index_intermediate.glb"/>
      </geometry>
    </visual>
    <collision>
      <origin xyz="0 0 0" rpy="0 0 0"/>
      <geometry>
        <mesh filename="../../hands/inspire_hand/meshes/collision/left_index_intermediate.obj"/>
      </geometry>
    </collision>
  </link>
  <joint name="ring_intermediate_joint" type="revolute">
    <origin xyz="-0.0024229 -0.032041 -0.001" rpy="0 0 0"/>
    <parent link="ring_proximal"/>
    <child link="ring_intermediate"/>
    <axis xyz="0 0 -1"/>
    <limit lower="-0.04545" upper="1.56" effort="1" velocity="0.5"/>
    <mimic joint="ring_proximal_joint" multiplier="1.06399" offset="-0.04545"/>
  </joint>
  <link name="pinky_proximal">
    <inertial>
      <origin xyz="0.001297 -0.011934 -0.0060001" rpy="0 0 0"/>
      <mass value="0.0042403"/>
      <inertia ixx="6.6211E-07" ixy="1.8461E-08" ixz="1.6907E-12" iyy="2.1167E-07" iyz="6.9334E-12" izz="6.9397E-07"/>
    </inertial>
    <visual>
      <origin xyz="0 0 0" rpy="0 0 0"/>
      <geometry>
        <mesh filename="../../hands/inspire_hand/meshes/visual/left_index_proximal.glb"/>
      </geometry>
    </visual>
    <collision>
      <origin xyz="0 0 0" rpy="0 0 0"/>
      <geometry>
        <mesh filename="../../hands/inspire_hand/meshes/collision/left_index_proximal.obj"/>
      </geometry>
    </collision>
  </link>
  <joint name="pinky_proximal_joint" type="revolute">
    <origin xyz="0.00028533 -0.13571 -0.025488" rpy="0.10472 0 0"/>
    <parent link="hand_base_link"/>
    <child link="pinky_proximal"/>
    <axis xyz="0 0 -1"/>
    <limit lower="0" upper="1.47" effort="1" velocity="0.5"/>
  </joint>
  <link name="pinky_intermediate">
    <inertial>
      <origin xyz="0.0024748 -0.016203 -0.0050031" rpy="0 0 0"/>
      <mass value="0.0035996"/>
      <inertia ixx="4.3913E-07" ixy="-4.1418E-08" ixz="3.7168E-11" iyy="7.0247E-08" iyz="-5.8613E-11" izz="4.4867E-07"/>
    </inertial>
    <visual>
      <origin xyz="0 0 0" rpy="0 0 0"/>
      <geometry>
        <mesh filename="../../hands/inspire_hand/meshes/visual/left_pinky_intermediate.glb"/>
      </geometry>
    </visual>
    <collision>
      <origin xyz="0 0 0" rpy="0 0 0"/>
      <geometry>
        <mesh filename="../../hands/inspire_hand/meshes/collision/left_pinky_intermediate.obj"/>
      </geometry>
    </collision>
  </link>
  <joint name="pinky_intermediate_joint" type="revolute">
    <origin xyz="-0.0024229 -0.032041 -0.001" rpy="0 0 0"/>
    <parent link="pinky_proximal"/>
    <child link="pinky_intermediate"/>
    <axis xyz="0 0 -1"/>
    <limit lower="-0.04545" upper="1.56" effort="1" velocity="0.5"/>
    <mimic joint="pinky_proximal_joint" multiplier="1.06399" offset="-0.04545"/>
  </joint>

  <!--  left fingertip-->
  <link name='thumb_tip'/>
  <joint name="thumb_tip_joint" type="fixed">
    <origin xyz="0.0202 -0.0140 -0.006" rpy="0 0 0"/>
    <parent link="thumb_distal"/>
    <child link="thumb_tip"/>
  </joint>
  <link name='index_tip'/>
  <joint name="index_tip_joint" type="fixed">
    <origin xyz="-0.0008 -0.045 -0.005" rpy="0 0 0"/>
    <parent link="index_intermediate"/>
    <child link="index_tip"/>
  </joint>
  <link name='middle_tip'/>
  <joint name="middle_tip_joint" type="fixed">
    <origin xyz="-0.001 -0.048 -0.005" rpy="0 0 0"/>
    <parent link="middle_intermediate"/>
    <child link="middle_tip"/>
  </joint>
  <link name='ring_tip'/>
  <joint name="ring_tip_joint" type="fixed">
    <origin xyz="-0.0008 -0.045 -0.005" rpy="0 0 0"/>
    <parent link="ring_intermediate"/>
    <child link="ring_tip"/>
  </joint>
  <link name='pinky_tip'/>
  <joint name="pinky_tip_joint" type="fixed">
    <origin xyz="-0.0008 -0.037 -0.005" rpy="0 0 0"/>
    <parent link="pinky_intermediate"/>
    <child link="pinky_tip"/>
  </joint>
</robot>
