<?xml version="1.0" ?>
<!-- =================================================================================== -->
<!-- |    This document was autogenerated by xacro from dexhand.xacro                  | -->
<!-- |    EDITING THIS FILE BY HAND IS NOT RECOMMENDED                                 | -->
<!-- =================================================================================== -->
<robot name="dexhand">
  <material name="silver">
    <color rgba="0.700 0.700 0.700 1.000"/>
  </material>
  <link name="base_link">
    <inertial>
      <origin rpy="0 0 0" xyz="-5.952490372344805e-18 -5.952490372344805e-18 0.00625299730853927"/>
      <mass value="0.3748186138447861"/>
      <inertia ixx="0.000121" ixy="0.0" ixz="-0.0" iyy="0.000121" iyz="-0.0" izz="0.000233"/>
    </inertial>
    <visual>
      <origin rpy="0 0 0" xyz="0 0 0"/>
      <geometry>
        <mesh filename="meshes/base_link.stl" scale="0.001 0.001 0.001"/>
      </geometry>
      <material name="silver"/>
    </visual>
    <collision>
      <origin rpy="0 0 0" xyz="0 0 0"/>
      <geometry>
        <mesh filename="meshes/base_link.stl" scale="0.001 0.001 0.001"/>
      </geometry>
    </collision>
  </link>
  <link name="forearm_1">
    <inertial>
      <origin rpy="0 0 0" xyz="-0.0045635525882340025 -0.0024890003495871478 0.09119374176848805"/>
      <mass value="2.2753127167166265"/>
      <inertia ixx="0.009336" ixy="-3.2e-05" ixz="0.000837" iyy="0.00912" iyz="4e-06" izz="0.00247"/>
    </inertial>
    <visual>
      <origin rpy="0 0 0" xyz="-0.0 -0.0 -0.0"/>
      <geometry>
        <mesh filename="meshes/forearm_1.stl" scale="0.001 0.001 0.001"/>
      </geometry>
      <material name="silver"/>
    </visual>
    <collision>
      <origin rpy="0 0 0" xyz="-0.0 -0.0 -0.0"/>
      <geometry>
        <mesh filename="meshes/forearm_1.stl" scale="0.001 0.001 0.001"/>
      </geometry>
    </collision>
  </link>
  <link name="wrist_lower_1">
    <inertial>
      <origin rpy="0 0 0" xyz="-3.0683763790256835e-05 0.02099365535807374 0.021635071099651598"/>
      <mass value="0.3236409508310491"/>
      <inertia ixx="0.000132" ixy="-0.0" ixz="-0.0" iyy="0.000118" iyz="-0.0" izz="0.000139"/>
    </inertial>
    <visual>
      <origin rpy="0 0 0" xyz="0.012 0.0217 -0.203"/>
      <geometry>
        <mesh filename="meshes/wrist_lower_1.stl" scale="0.001 0.001 0.001"/>
      </geometry>
      <material name="silver"/>
    </visual>
    <collision>
      <origin rpy="0 0 0" xyz="0.012 0.0217 -0.203"/>
      <geometry>
        <mesh filename="meshes/wrist_lower_1.stl" scale="0.001 0.001 0.001"/>
      </geometry>
    </collision>
  </link>
  <link name="wrist_upper_1">
    <inertial>
      <origin rpy="0 0 0" xyz="0.011943478530919125 1.976395235870395e-08 0.007146961841600852"/>
      <mass value="0.12131953205677495"/>
      <inertia ixx="3.3e-05" ixy="0.0" ixz="-0.0" iyy="2.2e-05" iyz="-0.0" izz="2.6e-05"/>
    </inertial>
    <visual>
      <origin rpy="0 0 0" xyz="0.02398 0.0007 -0.232"/>
      <geometry>
        <mesh filename="meshes/wrist_upper_1.stl" scale="0.001 0.001 0.001"/>
      </geometry>
      <material name="silver"/>
    </visual>
    <collision>
      <origin rpy="0 0 0" xyz="0.02398 0.0007 -0.232"/>
      <geometry>
        <mesh filename="meshes/wrist_upper_1.stl" scale="0.001 0.001 0.001"/>
      </geometry>
    </collision>
  </link>
  <link name="index_bulk_1">
    <inertial>
      <origin rpy="0 0 0" xyz="0.0019538368757692874 0.005732502869548347 0.0431073978685812"/>
      <mass value="0.10571474174321724"/>
      <inertia ixx="0.000112" ixy="-0.0" ixz="-7e-06" iyy="0.000114" iyz="-6e-06" izz="8e-06"/>
    </inertial>
    <visual>
      <origin rpy="0 0 0" xyz="0.01198 -0.0203 -0.255266"/>
      <geometry>
        <mesh filename="meshes/index_bulk_1.stl" scale="0.001 0.001 0.001"/>
      </geometry>
      <material name="silver"/>
    </visual>
    <collision>
      <origin rpy="0 0 0" xyz="0.01198 -0.0203 -0.255266"/>
      <geometry>
        <mesh filename="meshes/index_bulk_1.stl" scale="0.001 0.001 0.001"/>
      </geometry>
    </collision>
  </link>
  <link name="middle_bulk_1">
    <inertial>
      <origin rpy="0 0 0" xyz="0.010646950026404926 -0.0158135798135519 0.030689623412747002"/>
      <mass value="0.2319963124821001"/>
      <inertia ixx="0.000258" ixy="-1.4e-05" ixz="4e-05" iyy="0.000268" iyz="4.2e-05" izz="7.1e-05"/>
    </inertial>
    <visual>
      <origin rpy="0 0 0" xyz="0.01198 -0.0263 -0.255266"/>
      <geometry>
        <mesh filename="meshes/middle_bulk_1.stl" scale="0.001 0.001 0.001"/>
      </geometry>
      <material name="silver"/>
    </visual>
    <collision>
      <origin rpy="0 0 0" xyz="0.01198 -0.0263 -0.255266"/>
      <geometry>
        <mesh filename="meshes/middle_bulk_1.stl" scale="0.001 0.001 0.001"/>
      </geometry>
    </collision>
  </link>
  <link name="ring_bulk_1">
    <inertial>
      <origin rpy="0 0 0" xyz="0.003391811603104299 -0.010251243243741267 0.052778064056847374"/>
      <mass value="0.09588694429304498"/>
      <inertia ixx="7.4e-05" ixy="1e-06" ixz="-7e-06" iyy="7.4e-05" iyz="8e-06" izz="7e-06"/>
    </inertial>
    <visual>
      <origin rpy="0 0 0" xyz="0.01198 0.0027 -0.255266"/>
      <geometry>
        <mesh filename="meshes/ring_bulk_1.stl" scale="0.001 0.001 0.001"/>
      </geometry>
      <material name="silver"/>
    </visual>
    <collision>
      <origin rpy="0 0 0" xyz="0.01198 0.0027 -0.255266"/>
      <geometry>
        <mesh filename="meshes/ring_bulk_1.stl" scale="0.001 0.001 0.001"/>
      </geometry>
    </collision>
  </link>
  <link name="index_knuckle_1">
    <inertial>
      <origin rpy="0 0 0" xyz="0.007134673083101494 -0.000554087541311192 0.0011013348331223027"/>
      <mass value="0.016772407452453803"/>
      <inertia ixx="1e-06" ixy="0.0" ixz="-0.0" iyy="1e-06" iyz="0.0" izz="1e-06"/>
    </inertial>
    <visual>
      <origin rpy="0 0 0" xyz="0.015885 -0.030139 -0.340157"/>
      <geometry>
        <mesh filename="meshes/index_knuckle_1.stl" scale="0.001 0.001 0.001"/>
      </geometry>
      <material name="silver"/>
    </visual>
    <collision>
      <origin rpy="0 0 0" xyz="0.015885 -0.030139 -0.340157"/>
      <geometry>
        <mesh filename="meshes/index_knuckle_1.stl" scale="0.001 0.001 0.001"/>
      </geometry>
    </collision>
  </link>
  <link name="middle_knuckle_1">
    <inertial>
      <origin rpy="0 0 0" xyz="0.006935399474227786 3.095281810115008e-08 0.0009794888636301402"/>
      <mass value="0.016772407452453803"/>
      <inertia ixx="1e-06" ixy="0.0" ixz="-0.0" iyy="1e-06" iyz="0.0" izz="1e-06"/>
    </inertial>
    <visual>
      <origin rpy="0 0 0" xyz="0.014846 -0.0063 -0.346266"/>
      <geometry>
        <mesh filename="meshes/middle_knuckle_1.stl" scale="0.001 0.001 0.001"/>
      </geometry>
      <material name="silver"/>
    </visual>
    <collision>
      <origin rpy="0 0 0" xyz="0.014846 -0.0063 -0.346266"/>
      <geometry>
        <mesh filename="meshes/middle_knuckle_1.stl" scale="0.001 0.001 0.001"/>
      </geometry>
    </collision>
  </link>
  <link name="ring_knuckle_1">
    <inertial>
      <origin rpy="0 0 0" xyz="0.006918049206992899 0.000487529427883715 0.0009797412002321981"/>
      <mass value="0.016772407452453803"/>
      <inertia ixx="1e-06" ixy="-0.0" ixz="-0.0" iyy="1e-06" iyz="-0.0" izz="1e-06"/>
    </inertial>
    <visual>
      <origin rpy="0 0 0" xyz="0.013981 0.018338 -0.342345"/>
      <geometry>
        <mesh filename="meshes/ring_knuckle_1.stl" scale="0.001 0.001 0.001"/>
      </geometry>
      <material name="silver"/>
    </visual>
    <collision>
      <origin rpy="0 0 0" xyz="0.013981 0.018338 -0.342345"/>
      <geometry>
        <mesh filename="meshes/ring_knuckle_1.stl" scale="0.001 0.001 0.001"/>
      </geometry>
    </collision>
  </link>
  <link name="pinky_knuckle_1">
    <inertial>
      <origin rpy="0 0 0" xyz="0.006818820473942532 0.0011821873591725332 0.0010801856787559516"/>
      <mass value="0.016772407452453803"/>
      <inertia ixx="1e-06" ixy="-0.0" ixz="-0.0" iyy="1e-06" iyz="-0.0" izz="1e-06"/>
    </inertial>
    <visual>
      <origin rpy="0 0 0" xyz="0.013416 0.038988 -0.334029"/>
      <geometry>
        <mesh filename="meshes/pinky_knuckle_1.stl" scale="0.001 0.001 0.001"/>
      </geometry>
      <material name="silver"/>
    </visual>
    <collision>
      <origin rpy="0 0 0" xyz="0.013416 0.038988 -0.334029"/>
      <geometry>
        <mesh filename="meshes/pinky_knuckle_1.stl" scale="0.001 0.001 0.001"/>
      </geometry>
    </collision>
  </link>
  <link name="index_plp_1">
    <inertial>
      <origin rpy="0 0 0" xyz="-0.006869198158126683 -0.006033909809302226 0.022940465298997237"/>
      <mass value="0.051567105457974535"/>
      <inertia ixx="1.1e-05" ixy="-0.0" ixz="0.0" iyy="1.1e-05" iyz="-1e-06" izz="2e-06"/>
    </inertial>
    <visual>
      <origin rpy="0 0 0" xyz="0.007269 -0.037678 -0.343728"/>
      <geometry>
        <mesh filename="meshes/index_plp_1.stl" scale="0.001 0.001 0.001"/>
      </geometry>
      <material name="silver"/>
    </visual>
    <collision>
      <origin rpy="0 0 0" xyz="0.007269 -0.037678 -0.343728"/>
      <geometry>
        <mesh filename="meshes/index_plp_1.stl" scale="0.001 0.001 0.001"/>
      </geometry>
    </collision>
  </link>
  <link name="index_mlp_1">
<!--    <inertial>-->
<!--      <origin rpy="0 0 0" xyz="-0.0014672452336520724 -0.004861924263139264 0.014904028884496767"/>-->
<!--      <mass value="0.017288956361389173"/>-->
<!--      <inertia ixx="1e-06" ixy="-0.0" ixz="-0.0" iyy="1e-06" iyz="-0.0" izz="0.0"/>-->
<!--    </inertial>-->
    <visual>
      <origin rpy="0 0 0" xyz="0.011959 -0.038935 -0.388702"/>
      <geometry>
        <mesh filename="meshes/index_mlp_1.stl" scale="0.001 0.001 0.001"/>
      </geometry>
      <material name="silver"/>
    </visual>
    <collision>
      <origin rpy="0 0 0" xyz="0.011959 -0.038935 -0.388702"/>
      <geometry>
        <mesh filename="meshes/index_mlp_1.stl" scale="0.001 0.001 0.001"/>
      </geometry>
    </collision>
  </link>
  <link name="index_tip_1">
<!--    <inertial>-->
<!--      <origin rpy="0 0 0" xyz="-0.0008641939647346161 -0.005385771025884202 0.006769569897979"/>-->
<!--      <mass value="0.0160783570939756"/>-->
<!--      <inertia ixx="1e-06" ixy="-0.0" ixz="0.0" iyy="1e-06" iyz="-0.0" izz="0.0"/>-->
<!--    </inertial>-->
    <visual>
      <origin rpy="0 0 0" xyz="0.013327 -0.041154 -0.418589"/>
      <geometry>
        <mesh filename="meshes/index_tip_1.stl" scale="0.001 0.001 0.001"/>
      </geometry>
      <material name="silver"/>
    </visual>
    <collision>
      <origin rpy="0 0 0" xyz="0.013327 -0.041154 -0.418589"/>
      <geometry>
        <mesh filename="meshes/index_tip_1.stl" scale="0.001 0.001 0.001"/>
      </geometry>
    </collision>
  </link>
  <link name="middle_plp_1">
    <inertial>
      <origin rpy="0 0 0" xyz="-0.00594358104054421 -0.00819999164061916 0.02373210744114279"/>
      <mass value="0.05600912510930776"/>
      <inertia ixx="1.3e-05" ixy="0.0" ixz="0.0" iyy="1.3e-05" iyz="0.0" izz="2e-06"/>
    </inertial>
    <visual>
      <origin rpy="0 0 0" xyz="0.007096 -0.0143 -0.350266"/>
      <geometry>
        <mesh filename="meshes/middle_plp_1.stl" scale="0.001 0.001 0.001"/>
      </geometry>
      <material name="silver"/>
    </visual>
    <collision>
      <origin rpy="0 0 0" xyz="0.007096 -0.0143 -0.350266"/>
      <geometry>
        <mesh filename="meshes/middle_plp_1.stl" scale="0.001 0.001 0.001"/>
      </geometry>
    </collision>
  </link>
  <link name="middle_mlp_1">
    <inertial>
      <origin rpy="0 0 0" xyz="-0.0002942937668230401 -0.006300032078833909 0.01528820861860336"/>
      <mass value="0.019660714741942815"/>
      <inertia ixx="1e-06" ixy="0.0" ixz="-0.0" iyy="1e-06" iyz="0.0" izz="1e-06"/>
    </inertial>
    <visual>
      <origin rpy="0 0 0" xyz="0.011096 -0.0123 -0.397516"/>
      <geometry>
        <mesh filename="meshes/middle_mlp_1.stl" scale="0.001 0.001 0.001"/>
      </geometry>
      <material name="silver"/>
    </visual>
    <collision>
      <origin rpy="0 0 0" xyz="0.011096 -0.0123 -0.397516"/>
      <geometry>
        <mesh filename="meshes/middle_mlp_1.stl" scale="0.001 0.001 0.001"/>
      </geometry>
    </collision>
  </link>
  <link name="middle_tip_1">
<!--    <inertial>-->
<!--      <origin rpy="0 0 0" xyz="-0.0006361624064090965 -0.006200060330852975 0.0068547001404333785"/>-->
<!--      <mass value="0.0177222165691614"/>-->
<!--      <inertia ixx="1e-06" ixy="0.0" ixz="0.0" iyy="1e-06" iyz="0.0" izz="0.0"/>-->
<!--    </inertial>-->
    <visual>
      <origin rpy="0 0 0" xyz="0.011096 -0.0123 -0.429016"/>
      <geometry>
        <mesh filename="meshes/middle_tip_1.stl" scale="0.001 0.001 0.001"/>
      </geometry>
      <material name="silver"/>
    </visual>
    <collision>
      <origin rpy="0 0 0" xyz="0.011096 -0.0123 -0.429016"/>
      <geometry>
        <mesh filename="meshes/middle_tip_1.stl" scale="0.001 0.001 0.001"/>
      </geometry>
    </collision>
  </link>
  <link name="ring_plp_1">
    <inertial>
      <origin rpy="0 0 0" xyz="-0.004988778025381051 -0.011235452676283293 0.021431089299078443"/>
      <mass value="0.051607390430851795"/>
      <inertia ixx="1.1e-05" ixy="0.0" ixz="-0.0" iyy="1.1e-05" iyz="1e-06" izz="2e-06"/>
    </inertial>
    <visual>
      <origin rpy="0 0 0" xyz="0.006914 0.010213 -0.347254"/>
      <geometry>
        <mesh filename="meshes/ring_plp_1.stl" scale="0.001 0.001 0.001"/>
      </geometry>
      <material name="silver"/>
    </visual>
    <collision>
      <origin rpy="0 0 0" xyz="0.006914 0.010213 -0.347254"/>
      <geometry>
        <mesh filename="meshes/ring_plp_1.stl" scale="0.001 0.001 0.001"/>
      </geometry>
    </collision>
  </link>
  <link name="ring_mlp_1">
<!--    <inertial>-->
<!--      <origin rpy="0 0 0" xyz="0.00037321408367821905 -0.007644713369413636 0.013759338633879237"/>-->
<!--      <mass value="0.017289443732746056"/>-->
<!--      <inertia ixx="1e-06" ixy="0.0" ixz="-0.0" iyy="1e-06" iyz="0.0" izz="0.0"/>-->
<!--    </inertial>-->
    <visual>
      <origin rpy="0 0 0" xyz="0.010293 0.018042 -0.39168"/>
      <geometry>
        <mesh filename="meshes/ring_mlp_1.stl" scale="0.001 0.001 0.001"/>
      </geometry>
      <material name="silver"/>
    </visual>
    <collision>
      <origin rpy="0 0 0" xyz="0.010293 0.018042 -0.39168"/>
      <geometry>
        <mesh filename="meshes/ring_mlp_1.stl" scale="0.001 0.001 0.001"/>
      </geometry>
    </collision>
  </link>
  <link name="ring_tip_1">
<!--    <inertial>-->
<!--      <origin rpy="0 0 0" xyz="-2.475222624376619e-05 -0.006623152446546359 0.005616048262013451"/>-->
<!--      <mass value="0.016038982608931798"/>-->
<!--      <inertia ixx="1e-06" ixy="0.0" ixz="0.0" iyy="1e-06" iyz="0.0" izz="0.0"/>-->
<!--    </inertial>-->
    <visual>
      <origin rpy="0 0 0" xyz="0.010021 0.021513 -0.421477"/>
      <geometry>
        <mesh filename="meshes/ring_tip_1.stl" scale="0.001 0.001 0.001"/>
      </geometry>
      <material name="silver"/>
    </visual>
    <collision>
      <origin rpy="0 0 0" xyz="0.010021 0.021513 -0.421477"/>
      <geometry>
        <mesh filename="meshes/ring_tip_1.stl" scale="0.001 0.001 0.001"/>
      </geometry>
    </collision>
  </link>
  <link name="pinky_plp_1">
    <inertial>
      <origin rpy="0 0 0" xyz="-0.0038106689386204866 -0.012544392770237969 0.01824146705848928"/>
      <mass value="0.04272741599660885"/>
      <inertia ixx="8e-06" ixy="0.0" ixz="-0.0" iyy="8e-06" iyz="1e-06" izz="1e-06"/>
    </inertial>
    <visual>
      <origin rpy="0 0 0" xyz="0.007304 0.030449 -0.339487"/>
      <geometry>
        <mesh filename="meshes/pinky_plp_1.stl" scale="0.001 0.001 0.001"/>
      </geometry>
      <material name="silver"/>
    </visual>
    <collision>
      <origin rpy="0 0 0" xyz="0.007304 0.030449 -0.339487"/>
      <geometry>
        <mesh filename="meshes/pinky_plp_1.stl" scale="0.001 0.001 0.001"/>
      </geometry>
    </collision>
  </link>
  <link name="pinky_mlp_1">
<!--    <inertial>-->
<!--      <origin rpy="0 0 0" xyz="0.0010481249693847592 -0.007529779935539188 0.011942260100063107"/>-->
<!--      <mass value="0.012979924052628225"/>-->
<!--      <inertia ixx="1e-06" ixy="0.0" ixz="-0.0" iyy="1e-06" iyz="0.0" izz="0.0"/>-->
<!--    </inertial>-->
    <visual>
      <origin rpy="0 0 0" xyz="0.009816 0.041033 -0.37881"/>
      <geometry>
        <mesh filename="meshes/pinky_mlp_1.stl" scale="0.001 0.001 0.001"/>
      </geometry>
      <material name="silver"/>
    </visual>
    <collision>
      <origin rpy="0 0 0" xyz="0.009816 0.041033 -0.37881"/>
      <geometry>
        <mesh filename="meshes/pinky_mlp_1.stl" scale="0.001 0.001 0.001"/>
      </geometry>
    </collision>
  </link>
  <link name="pinky_tip_1">
<!--    <inertial>-->
<!--      <origin rpy="0 0 0" xyz="0.0005692184398215679 -0.006140507616860642 0.004252021497513858"/>-->
<!--      <mass value="0.012880734939160096"/>-->
<!--      <inertia ixx="1e-06" ixy="0.0" ixz="0.0" iyy="1e-06" iyz="0.0" izz="0.0"/>-->
<!--    </inertial>-->
    <visual>
      <origin rpy="0 0 0" xyz="0.009341 0.045718 -0.405396"/>
      <geometry>
        <mesh filename="meshes/pinky_tip_1.stl" scale="0.001 0.001 0.001"/>
      </geometry>
      <material name="silver"/>
    </visual>
    <collision>
      <origin rpy="0 0 0" xyz="0.009341 0.045718 -0.405396"/>
      <geometry>
        <mesh filename="meshes/pinky_tip_1.stl" scale="0.001 0.001 0.001"/>
      </geometry>
    </collision>
  </link>
  <link name="thumb_cmc_b_1">
    <inertial>
      <origin rpy="0 0 0" xyz="0.0033512527298519643 0.005810607163787045 -0.008141548652481512"/>
      <mass value="0.008494087027059793"/>
      <inertia ixx="0.0" ixy="-0.0" ixz="0.0" iyy="0.0" iyz="0.0" izz="0.0"/>
    </inertial>
    <visual>
      <origin rpy="0 0 0" xyz="-0.014937 -0.01879 -0.268001"/>
      <geometry>
        <mesh filename="meshes/thumb_cmc_b_1.stl" scale="0.001 0.001 0.001"/>
      </geometry>
      <material name="silver"/>
    </visual>
    <collision>
      <origin rpy="0 0 0" xyz="-0.014937 -0.01879 -0.268001"/>
      <geometry>
        <mesh filename="meshes/thumb_cmc_b_1.stl" scale="0.001 0.001 0.001"/>
      </geometry>
    </collision>
  </link>
  <link name="thumb_cmc_a_1">
    <inertial>
      <origin rpy="0 0 0" xyz="0.0029466810384300712 0.005054293341482698 0.005851296597689126"/>
      <mass value="0.015039242610946097"/>
      <inertia ixx="0.0" ixy="0.0" ixz="-0.0" iyy="0.0" iyz="-0.0" izz="0.0"/>
    </inertial>
    <visual>
      <origin rpy="0 0 0" xyz="-0.017759 -0.023693 -0.258808"/>
      <geometry>
        <mesh filename="meshes/thumb_cmc_a_1.stl" scale="0.001 0.001 0.001"/>
      </geometry>
      <material name="silver"/>
    </visual>
    <collision>
      <origin rpy="0 0 0" xyz="-0.017759 -0.023693 -0.258808"/>
      <geometry>
        <mesh filename="meshes/thumb_cmc_a_1.stl" scale="0.001 0.001 0.001"/>
      </geometry>
    </collision>
  </link>
  <link name="thumb_plp_1">
    <inertial>
      <origin rpy="0 0 0" xyz="0.005433746290735154 0.025637034957291558 0.01661470656693176"/>
      <mass value="0.06710748615776632"/>
      <inertia ixx="2e-05" ixy="-5e-06" ixz="-5e-06" iyy="1.5e-05" iyz="-9e-06" izz="1.3e-05"/>
    </inertial>
    <visual>
      <origin rpy="0 0 0" xyz="-0.028683 -0.026348 -0.26657"/>
      <geometry>
        <mesh filename="meshes/thumb_plp_1.stl" scale="0.001 0.001 0.001"/>
      </geometry>
      <material name="silver"/>
    </visual>
    <collision>
      <origin rpy="0 0 0" xyz="-0.028683 -0.026348 -0.26657"/>
      <geometry>
        <mesh filename="meshes/thumb_plp_1.stl" scale="0.001 0.001 0.001"/>
      </geometry>
    </collision>
  </link>
  <link name="thumb_mlp_1">
    <inertial>
      <origin rpy="0 0 0" xyz="0.002151568364903468 0.015611380274394432 0.012743956202626694"/>
      <mass value="0.025187203449803457"/>
      <inertia ixx="2e-06" ixy="-0.0" ixz="-0.0" iyy="2e-06" iyz="-1e-06" izz="2e-06"/>
    </inertial>
    <visual>
      <origin rpy="0 0 0" xyz="-0.049475 -0.066604 -0.306172"/>
      <geometry>
        <mesh filename="meshes/thumb_mlp_1.stl" scale="0.001 0.001 0.001"/>
      </geometry>
      <material name="silver"/>
    </visual>
    <collision>
      <origin rpy="0 0 0" xyz="-0.049475 -0.066604 -0.306172"/>
      <geometry>
        <mesh filename="meshes/thumb_mlp_1.stl" scale="0.001 0.001 0.001"/>
      </geometry>
    </collision>
  </link>
  <link name="thumb_tip_1">
    <inertial>
      <origin rpy="0 0 0" xyz="-0.0009246362325293633 0.010131321702323517 0.007474037055237359"/>
      <mass value="0.02316990761545859"/>
      <inertia ixx="2e-06" ixy="-0.0" ixz="-0.0" iyy="2e-06" iyz="-1e-06" izz="2e-06"/>
    </inertial>
    <visual>
      <origin rpy="0 0 0" xyz="-0.064312 -0.092065 -0.333221"/>
      <geometry>
        <mesh filename="meshes/thumb_tip_1.stl" scale="0.001 0.001 0.001"/>
      </geometry>
      <material name="silver"/>
    </visual>
    <collision>
      <origin rpy="0 0 0" xyz="-0.064312 -0.092065 -0.333221"/>
      <geometry>
        <mesh filename="meshes/thumb_tip_1.stl" scale="0.001 0.001 0.001"/>
      </geometry>
    </collision>
  </link>
  <link name="pinky_bulk_1">
    <inertial>
      <origin rpy="0 0 0" xyz="0.0027271468848747184 -0.022196857115917325 0.03641088783645313"/>
      <mass value="0.11417768838788588"/>
      <inertia ixx="0.000111" ixy="1e-06" ixz="-1e-05" iyy="0.000112" iyz="1.3e-05" izz="1e-05"/>
    </inertial>
    <visual>
      <origin rpy="0 0 0" xyz="0.01198 0.008743 -0.255266"/>
      <geometry>
        <mesh filename="meshes/pinky_bulk_1.stl" scale="0.001 0.001 0.001"/>
      </geometry>
      <material name="silver"/>
    </visual>
    <collision>
      <origin rpy="0 0 0" xyz="0.01198 0.008743 -0.255266"/>
      <geometry>
        <mesh filename="meshes/pinky_bulk_1.stl" scale="0.001 0.001 0.001"/>
      </geometry>
    </collision>
  </link>
  <joint name="flange" type="fixed">
    <origin rpy="0 0 0" xyz="0.0 0.0 0.0"/>
    <parent link="base_link"/>
    <child link="forearm_1"/>
  </joint>
  <joint name="wrist_pitch_lower" type="revolute">
    <origin rpy="0 0 0" xyz="-0.012 -0.0217 0.203"/>
    <parent link="forearm_1"/>
    <child link="wrist_lower_1"/>
    <axis xyz="0.0 -1.0 0.0"/>
    <limit effort="100" lower="-0.523599" upper="0.523599" velocity="100"/>
  </joint>
  <joint name="wrist_yaw" type="revolute">
    <origin rpy="0 0 0" xyz="-0.01198 0.021 0.029"/>
    <parent link="wrist_lower_1"/>
    <child link="wrist_upper_1"/>
    <axis xyz="-1.0 0.0 0.0"/>
    <limit effort="100" lower="-0.436332" upper="0.436332" velocity="100"/>
  </joint>
  <joint name="wrist_pitch_upper" type="revolute">
    <origin rpy="0 0 0" xyz="0.012 0.021 0.023266"/>
    <parent link="wrist_upper_1"/>
    <child link="index_bulk_1"/>
    <axis xyz="-0.0 -1.0 -0.0"/>
    <limit effort="100" lower="-0.349066" upper="0.349066" velocity="100"/>
  </joint>
  <joint name="middle_bulk" type="fixed">
    <origin rpy="0 0 0" xyz="0.0 0.006 0.0"/>
    <parent link="index_bulk_1"/>
    <child link="middle_bulk_1"/>
  </joint>
  <joint name="ring_bulk" type="fixed">
    <origin rpy="0 0 0" xyz="0.0 -0.029 0.0"/>
    <parent link="middle_bulk_1"/>
    <child link="ring_bulk_1"/>
  </joint>
  <joint name="index_yaw" type="revolute">
    <origin rpy="0 0 0" xyz="-0.003905 0.009839 0.084891"/>
    <parent link="index_bulk_1"/>
    <child link="index_knuckle_1"/>
    <axis xyz="-0.99606 0.086969 -0.017358"/>
    <limit effort="100" lower="-0.349066" upper="0.349066" velocity="100"/>
  </joint>
  <joint name="middle_yaw" type="revolute">
    <origin rpy="0 0 0" xyz="-0.002866 -0.02 0.091"/>
    <parent link="middle_bulk_1"/>
    <child link="middle_knuckle_1"/>
    <axis xyz="-1.0 0.0 0.0"/>
    <limit effort="100" lower="-0.349066" upper="0.349066" velocity="100"/>
  </joint>
  <joint name="ring_yaw" type="revolute">
    <origin rpy="0 0 0" xyz="-0.002001 -0.015638 0.087079"/>
    <parent link="ring_bulk_1"/>
    <child link="ring_knuckle_1"/>
    <axis xyz="-0.996234 -0.086694 -0.001008"/>
    <limit effort="100" lower="-0.349066" upper="0.349066" velocity="100"/>
  </joint>
  <joint name="pinky_yaw" type="revolute">
    <origin rpy="0 0 0" xyz="-0.001436 -0.030245 0.078763"/>
    <parent link="pinky_bulk_1"/>
    <child link="pinky_knuckle_1"/>
    <axis xyz="-0.98067 -0.194947 -0.016825"/>
    <limit effort="100" lower="-0.349066" upper="0.349066" velocity="100"/>
  </joint>
  <joint name="index_pitch" type="revolute">
    <origin rpy="0 0 0" xyz="0.008616 0.007539 0.003571"/>
    <parent link="index_knuckle_1"/>
    <child link="index_plp_1"/>
    <axis xyz="0.087977 0.993678 -0.069746"/>
    <limit effort="100" lower="0.0" upper="0.785398" velocity="100"/>
  </joint>
  <joint name="index_knuckle" type="revolute">
    <origin rpy="0 0 0" xyz="-0.00469 0.001257 0.044974"/>
    <parent link="index_plp_1"/>
    <child link="index_mlp_1"/>
    <axis xyz="0.087977 0.993678 -0.069746"/>
    <limit effort="100" lower="0.0" upper="0.785398" velocity="100"/>
  </joint>
  <joint name="index_tip" type="revolute">
    <origin rpy="0 0 0" xyz="-0.001368 0.002219 0.029887"/>
    <parent link="index_mlp_1"/>
    <child link="index_tip_1"/>
    <axis xyz="0.087977 0.993678 -0.069746"/>
    <limit effort="100" lower="0.0" upper="0.785398" velocity="100"/>
  </joint>
  <joint name="middle_pitch" type="revolute">
    <origin rpy="0 0 0" xyz="0.00775 0.008 0.004"/>
    <parent link="middle_knuckle_1"/>
    <child link="middle_plp_1"/>
    <axis xyz="0.0 1.0 0.0"/>
    <limit effort="100" lower="0.0" upper="0.785398" velocity="100"/>
  </joint>
  <joint name="middle_knuckle" type="revolute">
    <origin rpy="0 0 0" xyz="-0.004 -0.002 0.04725"/>
    <parent link="middle_plp_1"/>
    <child link="middle_mlp_1"/>
    <axis xyz="0.0 1.0 0.0"/>
    <limit effort="100" lower="0.0" upper="0.785398" velocity="100"/>
  </joint>
  <joint name="middle_tip" type="revolute">
    <origin rpy="0 0 0" xyz="0.0 0.0 0.0315"/>
    <parent link="middle_mlp_1"/>
    <child link="middle_tip_1"/>
    <axis xyz="0.0 1.0 0.0"/>
    <limit effort="100" lower="0.0" upper="0.785398" velocity="100"/>
  </joint>
  <joint name="ring_pitch" type="revolute">
    <origin rpy="0 0 0" xyz="0.007067 0.008125 0.004909"/>
    <parent link="ring_knuckle_1"/>
    <child link="ring_plp_1"/>
    <axis xyz="-0.086225 0.989495 0.116038"/>
    <limit effort="100" lower="0.0" upper="0.785398" velocity="100"/>
  </joint>
  <joint name="ring_knuckle" type="revolute">
    <origin rpy="0 0 0" xyz="-0.003379 -0.007829 0.044426"/>
    <parent link="ring_plp_1"/>
    <child link="ring_mlp_1"/>
    <axis xyz="-0.086225 0.989495 0.116038"/>
    <limit effort="100" lower="0.0" upper="0.785398" velocity="100"/>
  </joint>
  <joint name="ring_tip" type="revolute">
    <origin rpy="0 0 0" xyz="0.000272 -0.003471 0.029797"/>
    <parent link="ring_mlp_1"/>
    <child link="ring_tip_1"/>
    <axis xyz="-0.086225 0.989495 0.116038"/>
    <limit effort="100" lower="0.0" upper="0.785398" velocity="100"/>
  </joint>
  <joint name="pinky_pitch" type="revolute">
    <origin rpy="0 0 0" xyz="0.006112 0.008539 0.005458"/>
    <parent link="pinky_knuckle_1"/>
    <child link="pinky_plp_1"/>
    <axis xyz="-0.194878 0.965338 0.173624"/>
    <limit effort="100" lower="0.0" upper="0.785398" velocity="100"/>
  </joint>
  <joint name="pinky_knuckle" type="revolute">
    <origin rpy="0 0 0" xyz="-0.002512 -0.010584 0.039323"/>
    <parent link="pinky_plp_1"/>
    <child link="pinky_mlp_1"/>
    <axis xyz="-0.194878 0.965338 0.173624"/>
    <limit effort="100" lower="0.0" upper="0.785398" velocity="100"/>
  </joint>
  <joint name="pinky_tip" type="revolute">
    <origin rpy="0 0 0" xyz="0.000475 -0.004685 0.026586"/>
    <parent link="pinky_mlp_1"/>
    <child link="pinky_tip_1"/>
    <axis xyz="-0.194878 0.965338 0.173624"/>
    <limit effort="100" lower="0.0" upper="0.785398" velocity="100"/>
  </joint>
  <joint name="thumb_yaw" type="revolute">
    <origin rpy="0 0 0" xyz="0.026917 -0.00751 0.012735"/>
    <parent link="middle_bulk_1"/>
    <child link="thumb_cmc_b_1"/>
    <axis xyz="0.353553 0.612372 -0.707107"/>
    <limit effort="100" lower="0.0" upper="0.872665" velocity="100"/>
  </joint>
  <joint name="thumb_roll" type="revolute">
    <origin rpy="0 0 0" xyz="0.002822 0.004903 -0.009193"/>
    <parent link="thumb_cmc_b_1"/>
    <child link="thumb_cmc_a_1"/>
    <axis xyz="-0.35613 -0.610881 -0.707104"/>
    <limit effort="100" lower="0.0" upper="0.349066" velocity="100"/>
  </joint>
  <joint name="thumb_pitch" type="revolute">
    <origin rpy="0 0 0" xyz="0.010924 0.002655 0.007762"/>
    <parent link="thumb_cmc_a_1"/>
    <child link="thumb_plp_1"/>
    <axis xyz="0.864969 -0.501821 -0.002105"/>
    <limit effort="100" lower="0.0" upper="1.047198" velocity="100"/>
  </joint>
  <joint name="thumb_knuckle" type="revolute">
    <origin rpy="0 0 0" xyz="0.020792 0.040256 0.039602"/>
    <parent link="thumb_plp_1"/>
    <child link="thumb_mlp_1"/>
    <axis xyz="0.864969 -0.501821 -0.002105"/>
    <limit effort="100" lower="0.0" upper="0.785398" velocity="100"/>
  </joint>
  <joint name="thumb_tip" type="revolute">
    <origin rpy="0 0 0" xyz="0.014837 0.025461 0.027049"/>
    <parent link="thumb_mlp_1"/>
    <child link="thumb_tip_1"/>
    <axis xyz="0.864969 -0.501821 -0.002105"/>
    <limit effort="100" lower="0.0" upper="0.785398" velocity="100"/>
  </joint>
  <joint name="Rigid 43" type="fixed">
    <origin rpy="0 0 0" xyz="0.0 -0.006043 0.0"/>
    <parent link="ring_bulk_1"/>
    <child link="pinky_bulk_1"/>
  </joint>
</robot>
